<?xml version="1.0" ?>
<!-- =================================================================================== -->
<!-- |    This document was autogenerated by xacro from model.urdf.xacro               | -->
<!-- |    EDITING THIS FILE BY HAND IS NOT RECOMMENDED                                 | -->
<!-- =================================================================================== -->
<robot name="simple_car">
  <link name="base_link">
    <inertial>
      <origin rpy="0 0 0" xyz="0 0 0"/>
      <mass value="50"/>
      <inertia ixx="3.7083333333333335" ixy="0" ixz="0" iyy="17.708333333333332" iyz="0" izz="19.333333333333332"/>
    </inertial>
    <visual>
      <origin rpy="0 0 0" xyz="0 0 0"/>
      <geometry>
        <box size="2 0.8 0.5"/>
      </geometry>
    </visual>
    <collision>
      <origin rpy="0 0 0" xyz="0 0 0"/>
      <geometry>
        <box size="2 0.8 0.5"/>
      </geometry>
    </collision>
  </link>
  <link name="wheel_link_fl">
    <inertial>
      <origin rpy="0 0 0" xyz="0 0 0"/>
      <mass value="50"/>
      <inertia ixx="3.4999999999999996" ixy="0" ixz="0" iyy="3.4999999999999996" iyz="0" izz="6.25"/>
    </inertial>
    <visual>
      <origin rpy="0 0 0" xyz="0 0 0"/>
      <geometry>
        <cylinder length="0.3" radius="0.5"/>
      </geometry>
    </visual>
    <collision>
      <origin rpy="0 0 0" xyz="0 0 0"/>
      <geometry>
        <cylinder length="0.3" radius="0.5"/>
      </geometry>
    </collision>
  </link>
  <link name="wheel_link_rl">
    <inertial>
      <origin rpy="0 0 0" xyz="0 0 0"/>
      <mass value="50"/>
      <inertia ixx="3.4999999999999996" ixy="0" ixz="0" iyy="3.4999999999999996" iyz="0" izz="6.25"/>
    </inertial>
    <visual>
      <origin rpy="0 0 0" xyz="0 0 0"/>
      <geometry>
        <cylinder length="0.3" radius="0.5"/>
      </geometry>
    </visual>
    <collision>
      <origin rpy="0 0 0" xyz="0 0 0"/>
      <geometry>
        <cylinder length="0.3" radius="0.5"/>
      </geometry>
    </collision>
  </link>
  <link name="wheel_link_rr">
    <inertial>
      <origin rpy="0 0 0" xyz="0 0 0"/>
      <mass value="50"/>
      <inertia ixx="3.4999999999999996" ixy="0" ixz="0" iyy="3.4999999999999996" iyz="0" izz="6.25"/>
    </inertial>
    <visual>
      <origin rpy="0 0 0" xyz="0 0 0"/>
      <geometry>
        <cylinder length="0.3" radius="0.5"/>
      </geometry>
    </visual>
    <collision>
      <origin rpy="0 0 0" xyz="0 0 0"/>
      <geometry>
        <cylinder length="0.3" radius="0.5"/>
      </geometry>
    </collision>
  </link>
  <link name="wheel_link_fr">
    <inertial>
      <origin rpy="0 0 0" xyz="0 0 0"/>
      <mass value="50"/>
      <inertia ixx="3.4999999999999996" ixy="0" ixz="0" iyy="3.4999999999999996" iyz="0" izz="6.25"/>
    </inertial>
    <visual>
      <origin rpy="0 0 0" xyz="0 0 0"/>
      <geometry>
        <cylinder length="0.3" radius="0.5"/>
      </geometry>
    </visual>
    <collision>
      <origin rpy="0 0 0" xyz="0 0 0"/>
      <geometry>
        <cylinder length="0.3" radius="0.5"/>
      </geometry>
    </collision>
  </link>
  <joint name="joint_base_link_to_wheel_link_fl" type="continuous">
    <origin rpy="1.5707963267948966 0 0" xyz="2 2 0"/>
    <parent link="base_link"/>
    <child link="wheel_link_fl"/>
    <axis xyz="0 0 1"/>
  </joint>
  <joint name="joint_base_link_to_wheel_link_rl" type="continuous">
    <origin rpy="1.5707963267948966 0 0" xyz="-2 2 0"/>
    <parent link="base_link"/>
    <child link="wheel_link_rl"/>
    <axis xyz="0 0 1"/>
  </joint>
  <joint name="joint_base_link_to_wheel_link_rr" type="continuous">
    <origin rpy="1.5707963267948966 0 0" xyz="-2 -2 0"/>
    <parent link="base_link"/>
    <child link="wheel_link_rr"/>
    <axis xyz="0 0 1"/>
  </joint>
  <joint name="joint_base_link_to_wheel_link_fr" type="continuous">
    <origin rpy="1.5707963267948966 0 0" xyz="2 -2 0"/>
    <parent link="base_link"/>
    <child link="wheel_link_fr"/>
    <axis xyz="0 0 1"/>
  </joint>
</robot>
