<?xml version="1.0" ?>
<!-- =================================================================================== -->
<!-- |    This document was autogenerated by xacro from model.urdf.xacro               | -->
<!-- |    EDITING THIS FILE BY HAND IS NOT RECOMMENDED                                 | -->
<!-- =================================================================================== -->
<robot name="simple_car">
  <link name="base_link">
    <inertial>
      <origin rpy="0 0 0" xyz="0 0 0"/>
      <mass value="50"/>
      <inertia ixx="3.7083333333333335" ixy="0" ixz="0" iyy="17.708333333333332" iyz="0" izz="19.333333333333332"/>
    </inertial>
    <visual>
      <origin rpy="0 0 0" xyz="0 0 0"/>
      <geometry>
        <box size="2 0.8 0.5"/>
      </geometry>
    </visual>
    <collision>
      <origin rpy="0 0 0" xyz="0 0 0"/>
      <geometry>
        <box size="2 0.8 0.5"/>
      </geometry>
    </collision>
  </link>
  <link name="wheel_fl_base">
    <inertial>
      <origin rpy="0 0 0" xyz="0 0 0"/>
      <mass value="20"/>
      <inertia ixx="1" ixy="0" ixz="0" iyy="1" iyz="0" izz="1"/>
    </inertial>
    <visual>
      <geometry>
        <box size="0.3 0.3 0.3"/>
      </geometry>
    </visual>
  </link>
  <link name="wheel_fl_tire">
    <inertial>
      <origin rpy="0 0 0" xyz="0 0 0"/>
      <mass value="50"/>
      <inertia ixx="3.4999999999999996" ixy="0" ixz="0" iyy="3.4999999999999996" iyz="0" izz="6.25"/>
    </inertial>
    <visual>
      <origin rpy="0 0 0" xyz="0 0 0"/>
      <geometry>
        <cylinder length="0.3" radius="0.5"/>
      </geometry>
    </visual>
    <collision>
      <origin rpy="0 0 0" xyz="0 0 0"/>
      <geometry>
        <cylinder length="0.3" radius="0.5"/>
      </geometry>
    </collision>
  </link>
  <joint name="joint_base_link_to_wheel_fl_base" type="continuous">
    <origin rpy="0 0 0" xyz="2 2 0"/>
    <parent link="base_link"/>
    <child link="wheel_fl_base"/>
    <axis xyz="0 0 1"/>
  </joint>
  <joint name="joint_base_to_wheel_fl_tire" type="continuous">
    <origin rpy="1.5707963267948966 0 0" xyz="0 0 -1"/>
    <parent link="wheel_fl_base"/>
    <child link="wheel_fl_tire"/>
    <axis xyz="0 0 1"/>
  </joint>
  <gazebo reference="wheel_fl_base">
    <material>Gazebo/Blue</material>
  </gazebo>
  <gazebo reference="wheel_fl_tire">
    <material>Gazebo/Orange</material>
    <mu1>0.8</mu1>
    <mu2>0.5</mu2>
  </gazebo>
  <link name="wheel_rl_base">
    <inertial>
      <origin rpy="0 0 0" xyz="0 0 0"/>
      <mass value="20"/>
      <inertia ixx="1" ixy="0" ixz="0" iyy="1" iyz="0" izz="1"/>
    </inertial>
    <visual>
      <geometry>
        <box size="0.3 0.3 0.3"/>
      </geometry>
    </visual>
  </link>
  <link name="wheel_rl_tire">
    <inertial>
      <origin rpy="0 0 0" xyz="0 0 0"/>
      <mass value="50"/>
      <inertia ixx="3.4999999999999996" ixy="0" ixz="0" iyy="3.4999999999999996" iyz="0" izz="6.25"/>
    </inertial>
    <visual>
      <origin rpy="0 0 0" xyz="0 0 0"/>
      <geometry>
        <cylinder length="0.3" radius="0.5"/>
      </geometry>
    </visual>
    <collision>
      <origin rpy="0 0 0" xyz="0 0 0"/>
      <geometry>
        <cylinder length="0.3" radius="0.5"/>
      </geometry>
    </collision>
  </link>
  <joint name="joint_base_link_to_wheel_rl_base" type="continuous">
    <origin rpy="0 0 0" xyz="-2 2 0"/>
    <parent link="base_link"/>
    <child link="wheel_rl_base"/>
    <axis xyz="0 0 1"/>
  </joint>
  <joint name="joint_base_to_wheel_rl_tire" type="continuous">
    <origin rpy="1.5707963267948966 0 0" xyz="0 0 -1"/>
    <parent link="wheel_rl_base"/>
    <child link="wheel_rl_tire"/>
    <axis xyz="0 0 1"/>
  </joint>
  <gazebo reference="wheel_rl_base">
    <material>Gazebo/Blue</material>
  </gazebo>
  <gazebo reference="wheel_rl_tire">
    <material>Gazebo/Orange</material>
    <mu1>0.8</mu1>
    <mu2>0.5</mu2>
  </gazebo>
  <link name="wheel_rr_base">
    <inertial>
      <origin rpy="0 0 0" xyz="0 0 0"/>
      <mass value="20"/>
      <inertia ixx="1" ixy="0" ixz="0" iyy="1" iyz="0" izz="1"/>
    </inertial>
    <visual>
      <geometry>
        <box size="0.3 0.3 0.3"/>
      </geometry>
    </visual>
  </link>
  <link name="wheel_rr_tire">
    <inertial>
      <origin rpy="0 0 0" xyz="0 0 0"/>
      <mass value="50"/>
      <inertia ixx="3.4999999999999996" ixy="0" ixz="0" iyy="3.4999999999999996" iyz="0" izz="6.25"/>
    </inertial>
    <visual>
      <origin rpy="0 0 0" xyz="0 0 0"/>
      <geometry>
        <cylinder length="0.3" radius="0.5"/>
      </geometry>
    </visual>
    <collision>
      <origin rpy="0 0 0" xyz="0 0 0"/>
      <geometry>
        <cylinder length="0.3" radius="0.5"/>
      </geometry>
    </collision>
  </link>
  <joint name="joint_base_link_to_wheel_rr_base" type="continuous">
    <origin rpy="0 0 0" xyz="-2 -2 0"/>
    <parent link="base_link"/>
    <child link="wheel_rr_base"/>
    <axis xyz="0 0 1"/>
  </joint>
  <joint name="joint_base_to_wheel_rr_tire" type="continuous">
    <origin rpy="1.5707963267948966 0 0" xyz="0 0 -1"/>
    <parent link="wheel_rr_base"/>
    <child link="wheel_rr_tire"/>
    <axis xyz="0 0 1"/>
  </joint>
  <gazebo reference="wheel_rr_base">
    <material>Gazebo/Blue</material>
  </gazebo>
  <gazebo reference="wheel_rr_tire">
    <material>Gazebo/Orange</material>
    <mu1>0.8</mu1>
    <mu2>0.5</mu2>
  </gazebo>
  <link name="wheel_fr_base">
    <inertial>
      <origin rpy="0 0 0" xyz="0 0 0"/>
      <mass value="20"/>
      <inertia ixx="1" ixy="0" ixz="0" iyy="1" iyz="0" izz="1"/>
    </inertial>
    <visual>
      <geometry>
        <box size="0.3 0.3 0.3"/>
      </geometry>
    </visual>
  </link>
  <link name="wheel_fr_tire">
    <inertial>
      <origin rpy="0 0 0" xyz="0 0 0"/>
      <mass value="50"/>
      <inertia ixx="3.4999999999999996" ixy="0" ixz="0" iyy="3.4999999999999996" iyz="0" izz="6.25"/>
    </inertial>
    <visual>
      <origin rpy="0 0 0" xyz="0 0 0"/>
      <geometry>
        <cylinder length="0.3" radius="0.5"/>
      </geometry>
    </visual>
    <collision>
      <origin rpy="0 0 0" xyz="0 0 0"/>
      <geometry>
        <cylinder length="0.3" radius="0.5"/>
      </geometry>
    </collision>
  </link>
  <joint name="joint_base_link_to_wheel_fr_base" type="continuous">
    <origin rpy="0 0 0" xyz="2 -2 0"/>
    <parent link="base_link"/>
    <child link="wheel_fr_base"/>
    <axis xyz="0 0 1"/>
  </joint>
  <joint name="joint_base_to_wheel_fr_tire" type="continuous">
    <origin rpy="1.5707963267948966 0 0" xyz="0 0 -1"/>
    <parent link="wheel_fr_base"/>
    <child link="wheel_fr_tire"/>
    <axis xyz="0 0 1"/>
  </joint>
  <gazebo reference="wheel_fr_base">
    <material>Gazebo/Blue</material>
  </gazebo>
  <gazebo reference="wheel_fr_tire">
    <material>Gazebo/Orange</material>
    <mu1>0.8</mu1>
    <mu2>0.5</mu2>
  </gazebo>
</robot>
