<sdf version='1.7'>
  <model name='simple_car'>
    <link name='base_link'>
      <inertial>
        <pose>0 0 0 0 -0 0</pose>
        <mass>50</mass>
        <inertia>
          <ixx>3.70833</ixx>
          <ixy>0</ixy>
          <ixz>0</ixz>
          <iyy>17.7083</iyy>
          <iyz>0</iyz>
          <izz>19.3333</izz>
        </inertia>
      </inertial>
      <collision name='base_link_collision'>
        <pose>0 0 0 0 -0 0</pose>
        <geometry>
          <box>
            <size>2 0.8 0.5</size>
          </box>
        </geometry>
      </collision>
      <visual name='base_link_visual'>
        <pose>0 0 0 0 -0 0</pose>
        <geometry>
          <box>
            <size>2 0.8 0.5</size>
          </box>
        </geometry>
      </visual>
    </link>
    <joint name='joint_base_link_to_wheel_link_fl' type='revolute'>
      <pose relative_to='base_link'>2 2 0 1.5708 -0 0</pose>
      <parent>base_link</parent>
      <child>wheel_link_fl</child>
      <axis>
        <xyz>0 0 1</xyz>
        <limit>
          <lower>-1e+16</lower>
          <upper>1e+16</upper>
        </limit>
        <dynamics>
          <spring_reference>0</spring_reference>
          <spring_stiffness>0</spring_stiffness>
        </dynamics>
      </axis>
    </joint>
    <link name='wheel_link_fl'>
      <pose relative_to='joint_base_link_to_wheel_link_fl'>0 0 0 0 -0 0</pose>
      <inertial>
        <pose>0 0 0 0 -0 0</pose>
        <mass>50</mass>
        <inertia>
          <ixx>3.5</ixx>
          <ixy>0</ixy>
          <ixz>0</ixz>
          <iyy>3.5</iyy>
          <iyz>0</iyz>
          <izz>6.25</izz>
        </inertia>
      </inertial>
      <collision name='wheel_link_fl_collision'>
        <pose>0 0 0 0 -0 0</pose>
        <geometry>
          <cylinder>
            <length>0.3</length>
            <radius>0.5</radius>
          </cylinder>
        </geometry>
      </collision>
      <visual name='wheel_link_fl_visual'>
        <pose>0 0 0 0 -0 0</pose>
        <geometry>
          <cylinder>
            <length>0.3</length>
            <radius>0.5</radius>
          </cylinder>
        </geometry>
      </visual>
    </link>
    <joint name='joint_base_link_to_wheel_link_fr' type='revolute'>
      <pose relative_to='base_link'>2 -2 0 1.5708 -0 0</pose>
      <parent>base_link</parent>
      <child>wheel_link_fr</child>
      <axis>
        <xyz>0 0 1</xyz>
        <limit>
          <lower>-1e+16</lower>
          <upper>1e+16</upper>
        </limit>
        <dynamics>
          <spring_reference>0</spring_reference>
          <spring_stiffness>0</spring_stiffness>
        </dynamics>
      </axis>
    </joint>
    <link name='wheel_link_fr'>
      <pose relative_to='joint_base_link_to_wheel_link_fr'>0 0 0 0 -0 0</pose>
      <inertial>
        <pose>0 0 0 0 -0 0</pose>
        <mass>50</mass>
        <inertia>
          <ixx>3.5</ixx>
          <ixy>0</ixy>
          <ixz>0</ixz>
          <iyy>3.5</iyy>
          <iyz>0</iyz>
          <izz>6.25</izz>
        </inertia>
      </inertial>
      <collision name='wheel_link_fr_collision'>
        <pose>0 0 0 0 -0 0</pose>
        <geometry>
          <cylinder>
            <length>0.3</length>
            <radius>0.5</radius>
          </cylinder>
        </geometry>
      </collision>
      <visual name='wheel_link_fr_visual'>
        <pose>0 0 0 0 -0 0</pose>
        <geometry>
          <cylinder>
            <length>0.3</length>
            <radius>0.5</radius>
          </cylinder>
        </geometry>
      </visual>
    </link>
    <joint name='joint_base_link_to_wheel_link_rl' type='revolute'>
      <pose relative_to='base_link'>-2 2 0 1.5708 -0 0</pose>
      <parent>base_link</parent>
      <child>wheel_link_rl</child>
      <axis>
        <xyz>0 0 1</xyz>
        <limit>
          <lower>-1e+16</lower>
          <upper>1e+16</upper>
        </limit>
        <dynamics>
          <spring_reference>0</spring_reference>
          <spring_stiffness>0</spring_stiffness>
        </dynamics>
      </axis>
    </joint>
    <link name='wheel_link_rl'>
      <pose relative_to='joint_base_link_to_wheel_link_rl'>0 0 0 0 -0 0</pose>
      <inertial>
        <pose>0 0 0 0 -0 0</pose>
        <mass>50</mass>
        <inertia>
          <ixx>3.5</ixx>
          <ixy>0</ixy>
          <ixz>0</ixz>
          <iyy>3.5</iyy>
          <iyz>0</iyz>
          <izz>6.25</izz>
        </inertia>
      </inertial>
      <collision name='wheel_link_rl_collision'>
        <pose>0 0 0 0 -0 0</pose>
        <geometry>
          <cylinder>
            <length>0.3</length>
            <radius>0.5</radius>
          </cylinder>
        </geometry>
      </collision>
      <visual name='wheel_link_rl_visual'>
        <pose>0 0 0 0 -0 0</pose>
        <geometry>
          <cylinder>
            <length>0.3</length>
            <radius>0.5</radius>
          </cylinder>
        </geometry>
      </visual>
    </link>
    <joint name='joint_base_link_to_wheel_link_rr' type='revolute'>
      <pose relative_to='base_link'>-2 -2 0 1.5708 -0 0</pose>
      <parent>base_link</parent>
      <child>wheel_link_rr</child>
      <axis>
        <xyz>0 0 1</xyz>
        <limit>
          <lower>-1e+16</lower>
          <upper>1e+16</upper>
        </limit>
        <dynamics>
          <spring_reference>0</spring_reference>
          <spring_stiffness>0</spring_stiffness>
        </dynamics>
      </axis>
    </joint>
    <link name='wheel_link_rr'>
      <pose relative_to='joint_base_link_to_wheel_link_rr'>0 0 0 0 -0 0</pose>
      <inertial>
        <pose>0 0 0 0 -0 0</pose>
        <mass>50</mass>
        <inertia>
          <ixx>3.5</ixx>
          <ixy>0</ixy>
          <ixz>0</ixz>
          <iyy>3.5</iyy>
          <iyz>0</iyz>
          <izz>6.25</izz>
        </inertia>
      </inertial>
      <collision name='wheel_link_rr_collision'>
        <pose>0 0 0 0 -0 0</pose>
        <geometry>
          <cylinder>
            <length>0.3</length>
            <radius>0.5</radius>
          </cylinder>
        </geometry>
      </collision>
      <visual name='wheel_link_rr_visual'>
        <pose>0 0 0 0 -0 0</pose>
        <geometry>
          <cylinder>
            <length>0.3</length>
            <radius>0.5</radius>
          </cylinder>
        </geometry>
      </visual>
    </link>
  </model>
</sdf>
