<?xml version="1.0" ?>
<!-- =================================================================================== -->
<!-- |    This document was autogenerated by xacro from models/vehicle.urdf.xacro      | -->
<!-- |    EDITING THIS FILE BY HAND IS NOT RECOMMENDED                                 | -->
<!-- =================================================================================== -->
<robot name="vehicle" xmlns:xacro="http://www.ros.org/wiki/xacro">
  <link name="body">
    <inertial>
      <mass value="2000.0"/>
      <inertia ixx="750.0" ixy="0" ixz="0" iyy="541.6666666666666" iyz="0" izz="541.6666666666666"/>
    </inertial>
    <visual>
      <geometry>
        <box size="1.0 1.5 1.5"/>
      </geometry>
    </visual>
    <collision>
      <geometry>
        <box size="1.0 1.5 1.5"/>
      </geometry>
    </collision>
  </link>
  <link name="beam_left">
    <inertial>
      <mass value="200.0"/>
      <inertia ixx="2.9999999999999996" ixy="0" ixz="0" iyy="205.66666666666663" iyz="0" izz="205.66666666666663"/>
    </inertial>
    <visual>
      <geometry>
        <box size="3.5 0.3 0.3"/>
      </geometry>
    </visual>
    <collision>
      <geometry>
        <box size="3.5 0.3 0.3"/>
      </geometry>
    </collision>
  </link>
  <link name="beam_right">
    <inertial>
      <mass value="200.0"/>
      <inertia ixx="2.9999999999999996" ixy="0" ixz="0" iyy="205.66666666666663" iyz="0" izz="205.66666666666663"/>
    </inertial>
    <visual>
      <geometry>
        <box size="3.5 0.3 0.3"/>
      </geometry>
    </visual>
    <collision>
      <geometry>
        <box size="3.5 0.3 0.3"/>
      </geometry>
    </collision>
  </link>
  <link name="wheel_fl">
    <inertial>
      <mass value="200"/>
      <inertia ixx="20.666666666666668" ixy="0" ixz="0" iyy="20.666666666666668" iyz="0" izz="36.0"/>
    </inertial>
    <visual>
      <geometry>
        <cylinder length="0.4" radius="0.6"/>
      </geometry>
      <origin rpy="-1.57 0 0" xyz="0 0 0"/>
    </visual>
    <collision>
      <geometry>
        <cylinder length="0.4" radius="0.6"/>
      </geometry>
      <origin rpy="-1.57 0 0" xyz="0 0 0"/>
    </collision>
    <material name="tire">
      <color rgba="0.2392 0.2157 0.1686 1"/>
    </material>
    <contact>
      <!-- ground plane has friction value of 1, so use 
        friction value for tire-groundtype that is found online. -->
      <lateral_friction value="0.8"/>
    </contact>
  </link>
  <link name="wheel_rl">
    <inertial>
      <mass value="200"/>
      <inertia ixx="20.666666666666668" ixy="0" ixz="0" iyy="20.666666666666668" iyz="0" izz="36.0"/>
    </inertial>
    <visual>
      <geometry>
        <cylinder length="0.4" radius="0.6"/>
      </geometry>
      <origin rpy="-1.57 0 0" xyz="0 0 0"/>
    </visual>
    <collision>
      <geometry>
        <cylinder length="0.4" radius="0.6"/>
      </geometry>
      <origin rpy="-1.57 0 0" xyz="0 0 0"/>
    </collision>
    <material name="tire">
      <color rgba="0.2392 0.2157 0.1686 1"/>
    </material>
    <contact>
      <!-- ground plane has friction value of 1, so use 
        friction value for tire-groundtype that is found online. -->
      <lateral_friction value="0.8"/>
    </contact>
  </link>
  <link name="wheel_rr">
    <inertial>
      <mass value="200"/>
      <inertia ixx="20.666666666666668" ixy="0" ixz="0" iyy="20.666666666666668" iyz="0" izz="36.0"/>
    </inertial>
    <visual>
      <geometry>
        <cylinder length="0.4" radius="0.6"/>
      </geometry>
      <origin rpy="1.57 0 0" xyz="0 0 0"/>
    </visual>
    <collision>
      <geometry>
        <cylinder length="0.4" radius="0.6"/>
      </geometry>
      <origin rpy="1.57 0 0" xyz="0 0 0"/>
    </collision>
    <material name="tire">
      <color rgba="0.2392 0.2157 0.1686 1"/>
    </material>
    <contact>
      <!-- ground plane has friction value of 1, so use 
        friction value for tire-groundtype that is found online. -->
      <lateral_friction value="0.8"/>
    </contact>
  </link>
  <link name="wheel_fr">
    <inertial>
      <mass value="200"/>
      <inertia ixx="20.666666666666668" ixy="0" ixz="0" iyy="20.666666666666668" iyz="0" izz="36.0"/>
    </inertial>
    <visual>
      <geometry>
        <cylinder length="0.4" radius="0.6"/>
      </geometry>
      <origin rpy="1.57 0 0" xyz="0 0 0"/>
    </visual>
    <collision>
      <geometry>
        <cylinder length="0.4" radius="0.6"/>
      </geometry>
      <origin rpy="1.57 0 0" xyz="0 0 0"/>
    </collision>
    <material name="tire">
      <color rgba="0.2392 0.2157 0.1686 1"/>
    </material>
    <contact>
      <!-- ground plane has friction value of 1, so use 
        friction value for tire-groundtype that is found online. -->
      <lateral_friction value="0.8"/>
    </contact>
  </link>
  <!-- Beam joints -->
  <joint name="body_to_beam_left" type="fixed">
    <parent link="body"/>
    <child link="beam_left"/>
    <origin xyz="-1.25 0.6 0.9"/>
  </joint>
  <joint name="body_to_beam_right" type="fixed">
    <parent link="body"/>
    <child link="beam_right"/>
    <origin xyz="-1.25 -0.6 0.9"/>
  </joint>
  <joint name="body_to_wheel_fl" type="continuous">
    <parent link="body"/>
    <child link="wheel_fl"/>
    <origin xyz="0 1.05 -0.75"/>
    <axis xyz="0 1 0"/>
    <lateral_friction value="0.8"/>
  </joint>
  <joint name="body_to_wheel_rl" type="continuous">
    <parent link="beam_left"/>
    <child link="wheel_rl"/>
    <origin xyz="-1.75 0.4 -1.65"/>
    <axis xyz="0 1 0"/>
  </joint>
  <joint name="body_to_wheel_rr" type="continuous">
    <parent link="beam_right"/>
    <child link="wheel_rr"/>
    <origin xyz="-1.75 -0.4 -1.65"/>
    <axis xyz="0 1 0"/>
  </joint>
  <joint name="body_to_wheel_fr" type="continuous">
    <parent link="body"/>
    <child link="wheel_fr"/>
    <origin xyz="0 -1.05 -0.75"/>
    <axis xyz="0 1 0"/>
  </joint>
</robot>
